Workbook

Sheet Overview
B2: Corporate Strategy & Development Case Study
B4: Case Study: Robo-Advising
B5: Prepared by: Uyi Uwadiae
B6: Date: 12/09/2024
B8: ILLUSTRATIVE
B10: Assignment Brief:
B11: Firm is considering expanding its individual retail retirement investor platform by launching a Robo-Advisory account product. This model evaluates the Robo-Advisory market to support providing a recommendation on whether Firm should enter this competitive landscape.
B13: Objective:
B14: To analyze the market opportunity for Robo-Advisory services from 2023 to 2033, assess the competitive landscape, and provide strategic recommendations for Firm's market entry.
B16: Contents:
B17: This Excel file consists of three key tabs that contain detailed analyses and calculations to address the prompt's questions:
B19: Case Study Answers
... B38: In October 2026, Claude (an AI assistant made by Anthropic) updated this model at the author's request. The December 2024 submission is otherwise unchanged and the 2023-2033 time periods are the same. Setting the two new inputs on Module 1 (C27 and C28) to 0% removes the additions and leaves only the corrections.
B40: Change | C40: Where | D40: What changed and why
B41: New input: contribution growth | C41: Module 1, C27 (feeds R18:AB23) | D41: Annual growth applied to contribution dollars from 2024 on (2023 is the base year), on top of income growth and the stepped contribution rates. Default 1.0%; dropdown 0.0%-3.0%. An assumption added in 2026, not from the case prompt.
B42: New input: market appreciation | C42: Module 1, C28 (feeds D9:N9) | D42: Annual return on beginning-of-year AUM; the year's net contributions are added at year end. The case's assumption 3 asks for contributions, market appreciation and outflows, and the original had no appreciation. Default 5.0%; dropdown 0%-10%. An assumption added in 2026, not from the case prompt.
B43: Correction: net income | C43: Module 2, C9:M9 | D43: Net income summed rows 5-8, which included the market-share % row (adding $0.02M-$0.065M a year). It is now revenue + operating cost + initial capital.
B44: Correction: labor force growth | C44: Module 1, S7:AB12 | D44: Labor force growth was applied to withdrawals but not to contribution dollars. It now also scales annual income by age group.
B45: Correction: labor force growth 2030-2033 | C45: Module 1, K23:N23 | D45: These cells pointed at the 2026-2028 rate (+1.0%) instead of the 2029-2033 rate (-0.5%). They now use Assumptions G5, which changes the labor force counts that drive withdrawals.
B46: Correction: chart data | C46: Chart, D6:N6 | D46: Fee values were pasted numbers. They now link to Module 1 row 10 so the chart updates.
B47: Added: IRR and NPV timing | C47: Module 2, C19:C20 | D47: IRR of the net income row, and NPV with the 2023 investment at the start. NPV() in C18 treats the 2023 flow as the end of year 1.
B48: Housekeeping | C48: Workbook | D48: Replaced the pasted text box on this tab with cell text (and fixed two typos in it), corrected label spelling (Cumulative, Contributions, Withdrawal), and removed a hidden helper sheet and unused Capital IQ named ranges.
B50: Key outputs
B51: Metric | C51: Original (Dec 2024) | D51: Corrections only (new inputs at 0%) | E51: Updated (live)
B52: 2033 Robo-Advisor AUM ($M) | C52: 1586327.4 | D52: 1594985.8 | E52: ='Module 1'!N9 -> 2,250,257
B53: Robo-Advisor fee market, 2023-2033 ($M) | C53: 33314.577 | D53: 33411.121 | E53: =SUM('Module 1'!D10:N10) -> 42,313
B54: Firm payback year | C54: 2032 | D54: 2032 | E54: ='Module 2'!C16 -> 2031
B55: Firm NPV at the Module 2 discount rate ($M) | C55: 136.62368 | D55: 140.59051 | E55: ='Module 2'!C18 -> 491.09
B56: Firm IRR | C56: Not in original | D56: 0.066620776 | E56: ='Module 2'!C19 -> 13.6%
B57: Original and corrections-only figures are static values recorded at the time of the update. The Updated column is live.
B59: Not changed
B60: The written answers on the Case Study Answers tab are the original submission. The figures quoted there (about $1.6 trillion AUM, $33.3 billion fee revenue, $137 million NPV) come from the original model and no longer match the Updated outputs above. The linked cells D4, D5, D11 and D12 on that tab do update.
B62: Open items (recommendations not applied)
B63: - Cells labeled "Source" (Module 1 E36, E37, E41, E42; Module 2 S10) have no source, and the IRA share (Module 1 R27:AB27), robo market share (D8:N8) and 16-25 bracket (C26) are undocumented.
B64: - The 4% rule (Module 1 row 45) is applied to annual IRA contributions rather than accumulated balances.
B65: - Fees are charged on ending AUM (Module 1 row 10); average AUM is more standard.
B66: - Operating costs are fixed plus inflation, and the model has no taxes or terminal value.

Sheet Case Study Answers
B3: Module 1 | Questions | C3: Answers
B4: What is the total annual market opportunity for Robo-Advisor AUM during the period of 2023 – 2033? | D4: ='Module 1'!N9 -> $ 2,250,257 | E4: M
B5: What is the total annual market opportunity for Robo-Advisor fee revenue from 2023 – 2033, assuming the expectations of management fee reduction holds true? | D5: =SUM('Module 1'!D10:N10) -> $ 42,313 | E5: M
B6: What do you think explains the increasing adoption of Robo-Advisor IRAs at the expense of self-directed IRAs?
B7: What does the competitive landscape of Robo-Advice look like (e.g., market structure, competitors, barriers to entry, etc.), and based on your observations, what should Firm consider as it makes its decision?
B8: What do you think is driving the compression of future management fees for investment managers, robo-advisors, etc.? What are some strategic considerations to think about?
B9: Module 2 | Questions | C9: Answers
B10: Given the information provided in this document and in the excel, what is your evaluation of Firm’s economics of competing in the Robo-Advisory product service?
B11: What is Firm’s payback period (undiscounted point at which cumulative profits exceed cumulative investment) and NPV on this market entry opportunity over the period? | D11: ='Module 2'!C17 -> $ 8 | E11: Years
D12: ='Module 2'!C18 -> $ 491 | E12: M
B13: Given what you learned about the size and opportunities associated with the Robo-Advisory market, what is your evaluation of Firm’s decision to pursue market entry into Robo-Advisory?
B14: What are some key considerations that Firm should account for when deciding whether to enter this market?
B15: What is your recommendation to Firm regarding entering the Robo-Advisory product market? Should Firm enter or should Firm not enter?

Sheet Module 1
B4: Total IRA Contribution and Robo-Advisor Fee, by Year, $M | P4: Total Annual Income
C5: 2022 | D5: 2023 | E5: =D5+1 -> 2024 | F5: =E5+1 -> 2025 | G5: =F5+1 -> 2026 | H5: =G5+1 -> 2027 | I5: =H5+1 -> 2028 | J5: =I5+1 -> 2029 | K5: =J5+1 -> 2030 | L5: =K5+1 -> 2031 | ... N5: =M5+1 -> 2033 | Q5: Avg Annual Income Growth | R5: 2 | S5: 3 | T5: 3 | U5: 3 | V5: 3 | W5: 3 | X5: 4 | Y5: 4 | Z5: 4 | AA5: 4 | AB5: 4
B6: Annual IRA Contribution Adjusted | D6: =SUM(R53:R58)/$C$45 -> $ 328,625 | E6: =SUM(S53:S58)/$C$45 -> $ 405,933 | F6: =SUM(T53:T58)/$C$45 -> $ 420,517 | G6: =SUM(U53:U58)/$C$45 -> $ 459,950 | H6: =SUM(V53:V58)/$C$45 -> $ 483,348 | I6: =SUM(W53:W58)/$C$45 -> $ 507,837 | J6: =SUM(X53:X58)/$C$45 -> $ 507,184 | K6: =SUM(Y53:Y58)/$C$45 -> $ 519,069 | ... N6: =SUM(AB53:AB58)/$C$45 -> $ 556,118 | Q6: Age Bracket | R6: 2023 | S6: =R6+1 -> 2024 | T6: =S6+1 -> 2025 | U6: =T6+1 -> 2026 | V6: =U6+1 -> 2027 | W6: =V6+1 -> 2028 | X6: =W6+1 -> 2029 | Y6: =X6+1 -> 2030 | Z6: =Y6+1 -> 2031 | ... AB6: =AA6+1 -> 2033
B7: Robo-Advisor Market Size | D7: =D6*D8 -> $ 49,294 | E7: =E6*E8 -> $ 77,127 | F7: =F6*F8 -> $ 79,898 | G7: =G6*G8 -> $ 87,390 | H7: =H6*H8 -> $ 91,836 | I7: =I6*I8 -> $ 96,489 | J7: =J6*J8 -> $ 152,155 | K7: =K6*K8 -> $ 155,721 | ... N7: =N6*N8 -> $ 166,835 | Q7: 16-25 | R7: =VLOOKUP($Q7,Assumptions!$C$19:$F$24,R$5,FALSE)*D17 -> $ 225,792,000,000 | S7: =R7*(1+VLOOKUP($Q7,Assumptions!$C$19:$F$24,S$5,FALSE))*E$23 -> $ 230,279,616,000 | T7: =S7*(1+VLOOKUP($Q7,Assumptions!$C$19:$F$24,T$5,FALSE))*F$23 -> $ 234,856,423,368 | U7: =T7*(1+VLOOKUP($Q7,Assumptions!$C$19:$F$24,U$5,FALSE))*G$23 -> $ 243,135,112,292 | V7: =U7*(1+VLOOKUP($Q7,Assumptions!$C$19:$F$24,V$5,FALSE))*H$23 -> $ 251,705,625,000 | W7: =V7*(1+VLOOKUP($Q7,Assumptions!$C$19:$F$24,W$5,FALSE))*I$23 -> $ 260,578,248,281 | X7: =W7*(1+VLOOKUP($Q7,Assumptions!$C$19:$F$24,X$5,FALSE))*J$23 -> $ 263,164,487,395 | Y7: =X7*(1+VLOOKUP($Q7,Assumptions!$C$19:$F$24,Y$5,FALSE))*K$23 -> $ 265,776,394,933 | Z7: =Y7*(1+VLOOKUP($Q7,Assumptions!$C$19:$F$24,Z$5,FALSE))*L$23 -> $ 268,414,225,653 | ... AB7: =AA7*(1+VLOOKUP($Q7,Assumptions!$C$19:$F$24,AB$5,FALSE))*N$23 -> $ 273,768,688,343
B8: Market Share | D8: 0.15 | E8: 0.19 | F8: 0.19 | G8: 0.19 | H8: 0.19 | I8: 0.19 | J8: 0.3 | K8: 0.3 | L8: 0.3 | M8: 0.3 | N8: 0.3 | Q8: 26-35 | R8: =VLOOKUP($Q8,Assumptions!$C$19:$F$24,R$5,FALSE)*D18 -> $ 599,760,000,000 | S8: =R8*(1+VLOOKUP($Q8,Assumptions!$C$19:$F$24,S$5,FALSE))*E$23 -> $ 611,680,230,000 | T8: =S8*(1+VLOOKUP($Q8,Assumptions!$C$19:$F$24,T$5,FALSE))*F$23 -> $ 623,837,374,571 | U8: =T8*(1+VLOOKUP($Q8,Assumptions!$C$19:$F$24,U$5,FALSE))*G$23 -> $ 645,827,642,025 | V8: =U8*(1+VLOOKUP($Q8,Assumptions!$C$19:$F$24,V$5,FALSE))*H$23 -> $ 668,593,066,406 | W8: =V8*(1+VLOOKUP($Q8,Assumptions!$C$19:$F$24,W$5,FALSE))*I$23 -> $ 692,160,971,997 | X8: =W8*(1+VLOOKUP($Q8,Assumptions!$C$19:$F$24,X$5,FALSE))*J$23 -> $ 699,030,669,644 | Y8: =X8*(1+VLOOKUP($Q8,Assumptions!$C$19:$F$24,Y$5,FALSE))*K$23 -> $ 705,968,549,040 | Z8: =Y8*(1+VLOOKUP($Q8,Assumptions!$C$19:$F$24,Z$5,FALSE))*L$23 -> $ 712,975,286,890 | ... AB8: =AA8*(1+VLOOKUP($Q8,Assumptions!$C$19:$F$24,AB$5,FALSE))*N$23 -> $ 727,198,078,411
B9: AUM | C9: 400000 | D9: =C9*(1+$C$28)+D7 -> $ 469,294 | E9: =D9*(1+$C$28)+E7 -> $ 569,886 | F9: =E9*(1+$C$28)+F7 -> $ 678,278 | G9: =F9*(1+$C$28)+G7 -> $ 799,582 | H9: =G9*(1+$C$28)+H7 -> $ 931,398 | I9: =H9*(1+$C$28)+I7 -> $ 1,074,457 | J9: =I9*(1+$C$28)+J7 -> $ 1,280,335 | K9: =J9*(1+$C$28)+K7 -> $ 1,500,072 | ... N9: =M9*(1+$C$28)+N7 -> $ 2,250,257 | Q9: 36-45 | R9: =VLOOKUP($Q9,Assumptions!$C$19:$F$24,R$5,FALSE)*D19 -> $ 1,197,000,000,000 | S9: =R9*(1+VLOOKUP($Q9,Assumptions!$C$19:$F$24,S$5,FALSE))*E$23 -> $ 1,220,790,375,000 | T9: =S9*(1+VLOOKUP($Q9,Assumptions!$C$19:$F$24,T$5,FALSE))*F$23 -> $ 1,245,053,583,703 | U9: =T9*(1+VLOOKUP($Q9,Assumptions!$C$19:$F$24,U$5,FALSE))*G$23 -> $ 1,288,941,722,529 | V9: =U9*(1+VLOOKUP($Q9,Assumptions!$C$19:$F$24,V$5,FALSE))*H$23 -> $ 1,334,376,918,248 | W9: =V9*(1+VLOOKUP($Q9,Assumptions!$C$19:$F$24,W$5,FALSE))*I$23 -> $ 1,381,413,704,616 | X9: =W9*(1+VLOOKUP($Q9,Assumptions!$C$19:$F$24,X$5,FALSE))*J$23 -> $ 1,395,124,235,634 | Y9: =X9*(1+VLOOKUP($Q9,Assumptions!$C$19:$F$24,Y$5,FALSE))*K$23 -> $ 1,408,970,843,673 | Z9: =Y9*(1+VLOOKUP($Q9,Assumptions!$C$19:$F$24,Z$5,FALSE))*L$23 -> $ 1,422,954,879,296 | ... AB9: =AA9*(1+VLOOKUP($Q9,Assumptions!$C$19:$F$24,AB$5,FALSE))*N$23 -> $ 1,451,340,702,710
B10: Robo-Advisor Fee | D10: =D11*D9 -> $ 1,877 | E10: =E11*E9 -> $ 1,995 | F10: =F11*F9 -> $ 2,374 | G10: =G11*G9 -> $ 2,799 | H10: =H11*H9 -> $ 3,260 | I10: =I11*I9 -> $ 3,761 | J10: =J11*J9 -> $ 3,841 | K10: =K11*K9 -> $ 4,500 | ... N10: =N11*N9 -> $ 6,751 | Q10: 46-55 | R10: =VLOOKUP($Q10,Assumptions!$C$19:$F$24,R$5,FALSE)*D20 -> $ 1,344,000,000,000 | S10: =R10*(1+VLOOKUP($Q10,Assumptions!$C$19:$F$24,S$5,FALSE))*E$23 -> $ 1,370,712,000,000 | T10: =S10*(1+VLOOKUP($Q10,Assumptions!$C$19:$F$24,T$5,FALSE))*F$23 -> $ 1,397,954,901,000 | U10: =T10*(1+VLOOKUP($Q10,Assumptions!$C$19:$F$24,U$5,FALSE))*G$23 -> $ 1,447,232,811,260 | V10: =U10*(1+VLOOKUP($Q10,Assumptions!$C$19:$F$24,V$5,FALSE))*H$23 -> $ 1,498,247,767,857 | W10: =V10*(1+VLOOKUP($Q10,Assumptions!$C$19:$F$24,W$5,FALSE))*I$23 -> $ 1,551,061,001,674 | X10: =W10*(1+VLOOKUP($Q10,Assumptions!$C$19:$F$24,X$5,FALSE))*J$23 -> $ 1,566,455,282,116 | Y10: =X10*(1+VLOOKUP($Q10,Assumptions!$C$19:$F$24,Y$5,FALSE))*K$23 -> $ 1,582,002,350,791 | Z10: =Y10*(1+VLOOKUP($Q10,Assumptions!$C$19:$F$24,Z$5,FALSE))*L$23 -> $ 1,597,703,724,122 | ... AB10: =AA10*(1+VLOOKUP($Q10,Assumptions!$C$19:$F$24,AB$5,FALSE))*N$23 -> $ 1,629,575,525,850
B11: Mgmt Fee | D11: =D31 -> 0.40% | E11: =$E$31 -> 0.35% | F11: =$E$31 -> 0.35% | G11: =$E$31 -> 0.35% | H11: =$E$31 -> 0.35% | I11: =$E$31 -> 0.35% | J11: =$F$31 -> 0.30% | K11: =$F$31 -> 0.30% | L11: =$F$31 -> 0.30% | M11: =$F$31 -> 0.30% | N11: =$F$31 -> 0.30% | Q11: 56-70 | R11: =VLOOKUP($Q11,Assumptions!$C$19:$F$24,R$5,FALSE)*D21 -> $ 1,394,400,000,000 | S11: =R11*(1+VLOOKUP($Q11,Assumptions!$C$19:$F$24,S$5,FALSE))*E$23 -> $ 1,422,113,700,000 | T11: =S11*(1+VLOOKUP($Q11,Assumptions!$C$19:$F$24,T$5,FALSE))*F$23 -> $ 1,450,378,209,788 | U11: =T11*(1+VLOOKUP($Q11,Assumptions!$C$19:$F$24,U$5,FALSE))*G$23 -> $ 1,501,504,041,683 | V11: =U11*(1+VLOOKUP($Q11,Assumptions!$C$19:$F$24,V$5,FALSE))*H$23 -> $ 1,554,432,059,152 | W11: =V11*(1+VLOOKUP($Q11,Assumptions!$C$19:$F$24,W$5,FALSE))*I$23 -> $ 1,609,225,789,237 | X11: =W11*(1+VLOOKUP($Q11,Assumptions!$C$19:$F$24,X$5,FALSE))*J$23 -> $ 1,625,197,355,195 | Y11: =X11*(1+VLOOKUP($Q11,Assumptions!$C$19:$F$24,Y$5,FALSE))*K$23 -> $ 1,641,327,438,945 | Z11: =Y11*(1+VLOOKUP($Q11,Assumptions!$C$19:$F$24,Z$5,FALSE))*L$23 -> $ 1,657,617,613,777 | ... AB11: =AA11*(1+VLOOKUP($Q11,Assumptions!$C$19:$F$24,AB$5,FALSE))*N$23 -> $ 1,690,684,608,069
Q12: 70+ | R12: =VLOOKUP($Q12,Assumptions!$C$19:$F$24,R$5,FALSE)*D22 -> $ 766,080,000,000 | S12: =R12*(1+VLOOKUP($Q12,Assumptions!$C$19:$F$24,S$5,FALSE))*E$23 -> $ 781,305,840,000 | T12: =S12*(1+VLOOKUP($Q12,Assumptions!$C$19:$F$24,T$5,FALSE))*F$23 -> $ 796,834,293,570 | U12: =T12*(1+VLOOKUP($Q12,Assumptions!$C$19:$F$24,U$5,FALSE))*G$23 -> $ 824,922,702,418 | V12: =U12*(1+VLOOKUP($Q12,Assumptions!$C$19:$F$24,V$5,FALSE))*H$23 -> $ 854,001,227,679 | W12: =V12*(1+VLOOKUP($Q12,Assumptions!$C$19:$F$24,W$5,FALSE))*I$23 -> $ 884,104,770,954 | X12: =W12*(1+VLOOKUP($Q12,Assumptions!$C$19:$F$24,X$5,FALSE))*J$23 -> $ 892,879,510,806 | Y12: =X12*(1+VLOOKUP($Q12,Assumptions!$C$19:$F$24,Y$5,FALSE))*K$23 -> $ 901,741,339,951 | Z12: =Y12*(1+VLOOKUP($Q12,Assumptions!$C$19:$F$24,Z$5,FALSE))*L$23 -> $ 910,691,122,750 | ... AB12: =AA12*(1+VLOOKUP($Q12,Assumptions!$C$19:$F$24,AB$5,FALSE))*N$23 -> $ 928,858,049,735
Q13: Total | R13: =SUM(R7:R12) -> $ 5,527,032,000,000 | S13: =SUM(S7:S12) -> $ 5,636,881,761,000 | T13: =SUM(T7:T12) -> $ 5,748,914,786,000 | U13: =SUM(U7:U12) -> $ 5,951,564,032,206 | V13: =SUM(V7:V12) -> $ 6,161,356,664,342 | W13: =SUM(W7:W12) -> $ 6,378,544,486,760 | X13: =SUM(X7:X12) -> $ 6,441,851,540,791 | Y13: =SUM(Y7:Y12) -> $ 6,505,786,917,333 | ... AB13: =SUM(AB7:AB12) -> $ 6,701,425,653,118
B15: Labor Force Share, by Age Group
B16: Age Bracket | C16: 2023-2033 | D16: 2023 | E16: =D16+1 -> 2024 | F16: =E16+1 -> 2025 | G16: =F16+1 -> 2026 | H16: =G16+1 -> 2027 | I16: =H16+1 -> 2028 | J16: =I16+1 -> 2029 | K16: =J16+1 -> 2030 | L16: =K16+1 -> 2031 | ... N16: =M16+1 -> 2033 | P16: Total Contributions | Q16: % Contribution | R16: 2 | S16: 3 | T16: 3 | U16: 4 | V16: 4 | W16: 4 | X16: 5 | Y16: 5 | Z16: 5 | AA16: 5 | AB16: 5
B17: 16-25 | C17: 0.08 | D17: =C17*Assumptions!$D$5*$C$25*C26 -> 5,376,000 | E17: =D17*E$23 -> 5,349,120 | F17: =E17*F$23 -> 5,322,374 | G17: =F17*G$23 -> 5,375,598 | H17: =G17*H$23 -> 5,429,354 | I17: =H17*I$23 -> 5,483,648 | J17: =I17*J$23 -> 5,456,229 | K17: =J17*K$23 -> 5,428,948 | L17: =K17*L$23 -> 5,401,804 | ... N17: =M17*N$23 -> 5,347,921 | Q17: Age Bracket | R17: 2023 | S17: =R17+1 -> 2024 | T17: =S17+1 -> 2025 | U17: =T17+1 -> 2026 | V17: =U17+1 -> 2027 | W17: =V17+1 -> 2028 | X17: =W17+1 -> 2029 | Y17: =X17+1 -> 2030 | Z17: =Y17+1 -> 2031 | ... AB17: =AA17+1 -> 2033
B18: 26-35 | C18: 0.14 | D18: =C18*Assumptions!$D$5*$C$25 -> 11,760,000 | E18: =D18*E$23 -> 11,701,200 | F18: =E18*F$23 -> 11,642,694 | G18: =F18*G$23 -> 11,759,121 | H18: =G18*H$23 -> 11,876,712 | I18: =H18*I$23 -> 11,995,479 | J18: =I18*J$23 -> 11,935,502 | K18: =J18*K$23 -> 11,875,824 | L18: =K18*L$23 -> 11,816,445 | ... N18: =M18*N$23 -> 11,698,576 | Q18: 16-25 | R18: =R7*VLOOKUP($Q18,Assumptions!$C$28:$G$33,R$16,FALSE)*(1+$C$27)^(R$17-$R$17) -> $ 13,547,520,000 | S18: =S7*VLOOKUP($Q18,Assumptions!$C$28:$G$33,S$16,FALSE)*(1+$C$27)^(S$17-$R$17) -> $ 16,280,768,851 | T18: =T7*VLOOKUP($Q18,Assumptions!$C$28:$G$33,T$16,FALSE)*(1+$C$27)^(T$17-$R$17) -> $ 16,770,392,623 | U18: =U7*VLOOKUP($Q18,Assumptions!$C$28:$G$33,U$16,FALSE)*(1+$C$27)^(U$17-$R$17) -> $ 17,535,164,453 | V18: =V7*VLOOKUP($Q18,Assumptions!$C$28:$G$33,V$16,FALSE)*(1+$C$27)^(V$17-$R$17) -> $ 18,334,811,790 | W18: =W7*VLOOKUP($Q18,Assumptions!$C$28:$G$33,W$16,FALSE)*(1+$C$27)^(W$17-$R$17) -> $ 19,170,925,045 | X18: =X7*VLOOKUP($Q18,Assumptions!$C$28:$G$33,X$16,FALSE)*(1+$C$27)^(X$17-$R$17) -> $ 19,554,808,440 | Y18: =Y7*VLOOKUP($Q18,Assumptions!$C$28:$G$33,Y$16,FALSE)*(1+$C$27)^(Y$17-$R$17) -> $ 19,946,378,813 | ... AB18: =AB7*VLOOKUP($Q18,Assumptions!$C$28:$G$33,AB$16,FALSE)*(1+$C$27)^(AB$17-$R$17) -> $ 21,168,766,527
B19: 36-45 | C19: 0.19 | D19: =C19*Assumptions!$D$5*$C$25 -> 15,960,000 | E19: =D19*E$23 -> 15,880,200 | F19: =E19*F$23 -> 15,800,799 | G19: =F19*G$23 -> 15,958,807 | H19: =G19*H$23 -> 16,118,395 | I19: =H19*I$23 -> 16,279,579 | J19: =I19*J$23 -> 16,198,181 | K19: =J19*K$23 -> 16,117,190 | L19: =K19*L$23 -> 16,036,604 | ... N19: =M19*N$23 -> 15,876,639 | Q19: 26-35 | R19: =R8*VLOOKUP($Q19,Assumptions!$C$28:$G$33,R$16,FALSE)*(1+$C$27)^(R$17-$R$17) -> $ 47,980,800,000 | S19: =S8*VLOOKUP($Q19,Assumptions!$C$28:$G$33,S$16,FALSE)*(1+$C$27)^(S$17-$R$17) -> $ 61,779,703,230 | T19: =T8*VLOOKUP($Q19,Assumptions!$C$28:$G$33,T$16,FALSE)*(1+$C$27)^(T$17-$R$17) -> $ 63,637,650,580 | U19: =U8*VLOOKUP($Q19,Assumptions!$C$28:$G$33,U$16,FALSE)*(1+$C$27)^(U$17-$R$17) -> $ 66,539,686,541 | V19: =V8*VLOOKUP($Q19,Assumptions!$C$28:$G$33,V$16,FALSE)*(1+$C$27)^(V$17-$R$17) -> $ 69,574,062,596 | W19: =W8*VLOOKUP($Q19,Assumptions!$C$28:$G$33,W$16,FALSE)*(1+$C$27)^(W$17-$R$17) -> $ 72,746,813,786 | X19: =X8*VLOOKUP($Q19,Assumptions!$C$28:$G$33,X$16,FALSE)*(1+$C$27)^(X$17-$R$17) -> $ 74,203,514,172 | Y19: =Y8*VLOOKUP($Q19,Assumptions!$C$28:$G$33,Y$16,FALSE)*(1+$C$27)^(Y$17-$R$17) -> $ 75,689,383,890 | ... AB19: =AB8*VLOOKUP($Q19,Assumptions!$C$28:$G$33,AB$16,FALSE)*(1+$C$27)^(AB$17-$R$17) -> $ 80,327,908,697
B20: 46-55 | C20: 0.2 | D20: =C20*Assumptions!$D$5*$C$25 -> 16,800,000 | E20: =D20*E$23 -> 16,716,000 | F20: =E20*F$23 -> 16,632,420 | G20: =F20*G$23 -> 16,798,744 | H20: =G20*H$23 -> 16,966,732 | I20: =H20*I$23 -> 17,136,399 | J20: =I20*J$23 -> 17,050,717 | K20: =J20*K$23 -> 16,965,463 | L20: =K20*L$23 -> 16,880,636 | ... N20: =M20*N$23 -> 16,712,252 | Q20: 36-45 | R20: =R9*VLOOKUP($Q20,Assumptions!$C$28:$G$33,R$16,FALSE)*(1+$C$27)^(R$17-$R$17) -> $ 143,640,000,000 | S20: =S9*VLOOKUP($Q20,Assumptions!$C$28:$G$33,S$16,FALSE)*(1+$C$27)^(S$17-$R$17) -> $ 172,619,759,025 | T20: =T9*VLOOKUP($Q20,Assumptions!$C$28:$G$33,T$16,FALSE)*(1+$C$27)^(T$17-$R$17) -> $ 177,811,082,503 | U20: =U9*VLOOKUP($Q20,Assumptions!$C$28:$G$33,U$16,FALSE)*(1+$C$27)^(U$17-$R$17) -> $ 185,919,712,393 | V20: =V9*VLOOKUP($Q20,Assumptions!$C$28:$G$33,V$16,FALSE)*(1+$C$27)^(V$17-$R$17) -> $ 194,398,116,077 | W20: =W9*VLOOKUP($Q20,Assumptions!$C$28:$G$33,W$16,FALSE)*(1+$C$27)^(W$17-$R$17) -> $ 203,263,156,166 | X20: =X9*VLOOKUP($Q20,Assumptions!$C$28:$G$33,X$16,FALSE)*(1+$C$27)^(X$17-$R$17) -> $ 207,333,348,420 | Y20: =Y9*VLOOKUP($Q20,Assumptions!$C$28:$G$33,Y$16,FALSE)*(1+$C$27)^(Y$17-$R$17) -> $ 211,485,043,223 | ... AB20: =AB9*VLOOKUP($Q20,Assumptions!$C$28:$G$33,AB$16,FALSE)*(1+$C$27)^(AB$17-$R$17) -> $ 224,445,627,241
B21: 56-70 | C21: 0.2 | D21: =C21*Assumptions!$D$5*$C$25 -> 16,800,000 | E21: =D21*E$23 -> 16,716,000 | F21: =E21*F$23 -> 16,632,420 | G21: =F21*G$23 -> 16,798,744 | H21: =G21*H$23 -> 16,966,732 | I21: =H21*I$23 -> 17,136,399 | J21: =I21*J$23 -> 17,050,717 | K21: =J21*K$23 -> 16,965,463 | L21: =K21*L$23 -> 16,880,636 | ... N21: =M21*N$23 -> 16,712,252 | Q21: 46-55 | R21: =R10*VLOOKUP($Q21,Assumptions!$C$28:$G$33,R$16,FALSE)*(1+$C$27)^(R$17-$R$17) -> $ 215,040,000,000 | S21: =S10*VLOOKUP($Q21,Assumptions!$C$28:$G$33,S$16,FALSE)*(1+$C$27)^(S$17-$R$17) -> $ 249,195,441,600 | T21: =T10*VLOOKUP($Q21,Assumptions!$C$28:$G$33,T$16,FALSE)*(1+$C$27)^(T$17-$R$17) -> $ 256,689,683,012 | U21: =U10*VLOOKUP($Q21,Assumptions!$C$28:$G$33,U$16,FALSE)*(1+$C$27)^(U$17-$R$17) -> $ 283,306,228,408 | V21: =V10*VLOOKUP($Q21,Assumptions!$C$28:$G$33,V$16,FALSE)*(1+$C$27)^(V$17-$R$17) -> $ 296,225,700,689 | W21: =W10*VLOOKUP($Q21,Assumptions!$C$28:$G$33,W$16,FALSE)*(1+$C$27)^(W$17-$R$17) -> $ 309,734,333,205 | X21: =X10*VLOOKUP($Q21,Assumptions!$C$28:$G$33,X$16,FALSE)*(1+$C$27)^(X$17-$R$17) -> $ 349,193,007,866 | Y21: =Y10*VLOOKUP($Q21,Assumptions!$C$28:$G$33,Y$16,FALSE)*(1+$C$27)^(Y$17-$R$17) -> $ 356,185,335,954 | ... AB21: =AB10*VLOOKUP($Q21,Assumptions!$C$28:$G$33,AB$16,FALSE)*(1+$C$27)^(AB$17-$R$17) -> $ 378,013,687,985
B22: 70+ | C22: 0.19 | D22: =C22*Assumptions!$D$5*$C$25 -> 15,960,000 | E22: =D22*E$23 -> 15,880,200 | F22: =E22*F$23 -> 15,800,799 | G22: =F22*G$23 -> 15,958,807 | H22: =G22*H$23 -> 16,118,395 | I22: =H22*I$23 -> 16,279,579 | J22: =I22*J$23 -> 16,198,181 | K22: =J22*K$23 -> 16,117,190 | L22: =K22*L$23 -> 16,036,604 | ... N22: =M22*N$23 -> 15,876,639 | Q22: 56-70 | R22: =R11*VLOOKUP($Q22,Assumptions!$C$28:$G$33,R$16,FALSE)*(1+$C$27)^(R$17-$R$17) -> $ 250,992,000,000 | S22: =S11*VLOOKUP($Q22,Assumptions!$C$28:$G$33,S$16,FALSE)*(1+$C$27)^(S$17-$R$17) -> $ 301,630,315,770 | T22: =T11*VLOOKUP($Q22,Assumptions!$C$28:$G$33,T$16,FALSE)*(1+$C$27)^(T$17-$R$17) -> $ 310,701,470,479 | U22: =U11*VLOOKUP($Q22,Assumptions!$C$28:$G$33,U$16,FALSE)*(1+$C$27)^(U$17-$R$17) -> $ 340,340,245,443 | V22: =V11*VLOOKUP($Q22,Assumptions!$C$28:$G$33,V$16,FALSE)*(1+$C$27)^(V$17-$R$17) -> $ 355,860,611,486 | W22: =W11*VLOOKUP($Q22,Assumptions!$C$28:$G$33,W$16,FALSE)*(1+$C$27)^(W$17-$R$17) -> $ 372,088,745,021 | X22: =X11*VLOOKUP($Q22,Assumptions!$C$28:$G$33,X$16,FALSE)*(1+$C$27)^(X$17-$R$17) -> $ 414,043,137,898 | Y22: =Y11*VLOOKUP($Q22,Assumptions!$C$28:$G$33,Y$16,FALSE)*(1+$C$27)^(Y$17-$R$17) -> $ 422,334,041,202 | ... AB22: =AB11*VLOOKUP($Q22,Assumptions!$C$28:$G$33,AB$16,FALSE)*(1+$C$27)^(AB$17-$R$17) -> $ 448,216,230,040
B23: Labor Force Growth Rate | E23: =1+Assumptions!$E$5 -> 99.5% | F23: =1+Assumptions!$E$5 -> 99.5% | G23: =1+Assumptions!$F$5 -> 101.0% | H23: =1+Assumptions!$F$5 -> 101.0% | I23: =1+Assumptions!$F$5 -> 101.0% | J23: =1+Assumptions!$G$5 -> 99.5% | K23: =1+Assumptions!$G$5 -> 99.5% | L23: =1+Assumptions!$G$5 -> 99.5% | M23: =1+Assumptions!$G$5 -> 99.5% | N23: =1+Assumptions!$G$5 -> 99.5% | Q23: 70+ | R23: =R12*VLOOKUP($Q23,Assumptions!$C$28:$G$33,R$16,FALSE)*(1+$C$27)^(R$17-$R$17) -> $ - | S23: =S12*VLOOKUP($Q23,Assumptions!$C$28:$G$33,S$16,FALSE)*(1+$C$27)^(S$17-$R$17) -> $ - | T23: =T12*VLOOKUP($Q23,Assumptions!$C$28:$G$33,T$16,FALSE)*(1+$C$27)^(T$17-$R$17) -> $ - | U23: =U12*VLOOKUP($Q23,Assumptions!$C$28:$G$33,U$16,FALSE)*(1+$C$27)^(U$17-$R$17) -> $ - | V23: =V12*VLOOKUP($Q23,Assumptions!$C$28:$G$33,V$16,FALSE)*(1+$C$27)^(V$17-$R$17) -> $ - | W23: =W12*VLOOKUP($Q23,Assumptions!$C$28:$G$33,W$16,FALSE)*(1+$C$27)^(W$17-$R$17) -> $ - | X23: =X12*VLOOKUP($Q23,Assumptions!$C$28:$G$33,X$16,FALSE)*(1+$C$27)^(X$17-$R$17) -> $ - | Y23: =Y12*VLOOKUP($Q23,Assumptions!$C$28:$G$33,Y$16,FALSE)*(1+$C$27)^(Y$17-$R$17) -> $ - | ... AB23: =AB12*VLOOKUP($Q23,Assumptions!$C$28:$G$33,AB$16,FALSE)*(1+$C$27)^(AB$17-$R$17) -> $ -
Q24: Total | R24: =SUM(R18:R23) -> $ 671,200,320,000 | S24: =SUM(S18:S23) -> $ 801,505,988,476 | T24: =SUM(T18:T23) -> $ 825,610,279,197 | U24: =SUM(U18:U23) -> $ 893,641,037,237 | V24: =SUM(V18:V23) -> $ 934,393,302,638 | W24: =SUM(W18:W23) -> $ 977,003,973,222 | X24: =SUM(X18:X23) -> $ 1,064,327,816,797 | Y24: =SUM(Y18:Y23) -> $ 1,085,640,183,082 | ... AB24: =SUM(AB18:AB23) -> $ 1,152,172,220,490
B25: % contributing | C25: 0.5 | R25: =R24/R13 -> 12% | S25: =S24/S13 -> 14% | T25: =T24/T13 -> 14% | U25: =U24/U13 -> 15% | V25: =V24/V13 -> 15% | W25: =W24/W13 -> 15% | X25: =X24/X13 -> 17% | Y25: =Y24/Y13 -> 17% | ... AB25: =AB24/AB13 -> 17%
B26: 16-25 Bracket % | C26: 0.8
B27: Contribution growth | C27: 0.01 | D27: Added 2026: annual growth in contribution dollars from 2024 (2023 is the base year). Dropdown. | P27: IRA Contributions | Q27: % IRA | R27: 0.6 | S27: 0.6 | T27: 0.6 | U27: 0.6 | V27: 0.6 | W27: 0.6 | X27: 0.55 | Y27: 0.55 | Z27: 0.55 | AA27: 0.55 | AB27: 0.55
B28: Market appreciation | C28: 0.05 | D28: Added 2026: annual return on beginning-of-year AUM; net contributions added at year end. Dropdown. | Q28: Age Bracket | R28: 2023 | S28: =R28+1 -> 2024 | T28: =S28+1 -> 2025 | U28: =T28+1 -> 2026 | V28: =U28+1 -> 2027 | W28: =V28+1 -> 2028 | X28: =W28+1 -> 2029 | Y28: =X28+1 -> 2030 | Z28: =Y28+1 -> 2031 | ... AB28: =AA28+1 -> 2033
B29: Robo-Advisory Management Fee Revenues | Q29: 16-25 | R29: =R18*R$27 -> $ 8,128,512,000 | S29: =S18*S$27 -> $ 9,768,461,311 | T29: =T18*T$27 -> $ 10,062,235,574 | U29: =U18*U$27 -> $ 10,521,098,672 | V29: =V18*V$27 -> $ 11,000,887,074 | W29: =W18*W$27 -> $ 11,502,555,027 | X29: =X18*X$27 -> $ 10,755,144,642 | Y29: =Y18*Y$27 -> $ 10,970,508,347 | ... AB29: =AB18*AB$27 -> $ 11,642,821,590
D30: 2023 | E30: 2024 - 2028 | F30: 2029 -2033 | Q30: 26-35 | R30: =R19*R$27 -> $ 28,788,480,000 | S30: =S19*S$27 -> $ 37,067,821,938 | T30: =T19*T$27 -> $ 38,182,590,348 | U30: =U19*U$27 -> $ 39,923,811,924 | V30: =V19*V$27 -> $ 41,744,437,558 | W30: =W19*W$27 -> $ 43,648,088,271 | X30: =X19*X$27 -> $ 40,811,932,794 | Y30: =Y19*Y$27 -> $ 41,629,161,140 | ... AB30: =AB19*AB$27 -> $ 44,180,349,783
B31: Average Annualized Mgmt Fee % | D31: 0.004 | E31: 0.0035 | F31: 0.003 | Q31: 36-45 | R31: =R20*R$27 -> $ 86,184,000,000 | S31: =S20*S$27 -> $ 103,571,855,415 | T31: =T20*T$27 -> $ 106,686,649,502 | U31: =U20*U$27 -> $ 111,551,827,436 | V31: =V20*V$27 -> $ 116,638,869,646 | W31: =W20*W$27 -> $ 121,957,893,699 | X31: =X20*X$27 -> $ 114,033,341,631 | Y31: =Y20*Y$27 -> $ 116,316,773,772 | ... AB31: =AB20*AB$27 -> $ 123,445,094,983
B32: Average Annualized Mgmt Fee $ | D32: =SUM(D10) -> $ 1,877 | E32: =SUM(E10:I10) -> $ 14,188 | F32: =SUM(J10:N10) -> $ 26,248 | Q32: 46-55 | R32: =R21*R$27 -> $ 129,024,000,000 | S32: =S21*S$27 -> $ 149,517,264,960 | T32: =T21*T$27 -> $ 154,013,809,807 | U32: =U21*U$27 -> $ 169,983,737,045 | V32: =V21*V$27 -> $ 177,735,420,413 | W32: =W21*W$27 -> $ 185,840,599,923 | X32: =X21*X$27 -> $ 192,056,154,326 | Y32: =Y21*Y$27 -> $ 195,901,934,775 | ... AB32: =AB21*AB$27 -> $ 207,907,528,392
Q33: 56-70 | R33: =R22*R$27 -> $ 150,595,200,000 | S33: =S22*S$27 -> $ 180,978,189,462 | T33: =T22*T$27 -> $ 186,420,882,287 | U33: =U22*U$27 -> $ 204,204,147,266 | V33: =V22*V$27 -> $ 213,516,366,891 | W33: =W22*W$27 -> $ 223,253,247,013 | X33: =X22*X$27 -> $ 227,723,725,844 | Y33: =Y22*Y$27 -> $ 232,283,722,661 | ... AB33: =AB22*AB$27 -> $ 246,518,926,522
Q34: 70+ | R34: =R23*R$27 -> $ - | S34: =S23*S$27 -> $ - | T34: =T23*T$27 -> $ - | U34: =U23*U$27 -> $ - | V34: =V23*V$27 -> $ - | W34: =W23*W$27 -> $ - | X34: =X23*X$27 -> $ - | Y34: =Y23*Y$27 -> $ - | ... AB34: =AB23*AB$27 -> $ -
B35: Withdrawal Assumptions | Q35: Total | R35: =SUM(R29:R34) -> $ 402,720,192,000 | S35: =SUM(S29:S34) -> $ 480,903,593,086 | T35: =SUM(T29:T34) -> $ 495,366,167,518 | U35: =SUM(U29:U34) -> $ 536,184,622,342 | V35: =SUM(V29:V34) -> $ 560,635,981,583 | W35: =SUM(W29:W34) -> $ 586,202,383,933 | X35: =SUM(X29:X34) -> $ 585,380,299,238 | Y35: =SUM(Y29:Y34) -> $ 597,102,100,695 | ... AB35: =SUM(AB29:AB34) -> $ 633,694,721,270
B36: 0.04 | C36: 4% Rule | E36: Source
B37: 0.4 | C37: 2/5 Make early withdrawls | E37: Source
B38: 0.2 | C38: Assumption for 36-45 | P38: IRA Withdrawals
B39: 0.05 | C39: Assumption for 26-35 | Q39: Year | R39: 3 | S39: =R39+1 -> 4 | T39: =S39+1 -> 5 | U39: =T39+1 -> 6 | V39: =U39+1 -> 7 | W39: =V39+1 -> 8 | X39: =W39+1 -> 9 | Y39: =X39+1 -> 10 | Z39: =Y39+1 -> 11 | ... AB39: =AA39+1 -> 13
B40: 0.01 | C40: Assumption for 16-25 | Q40: Age Bracket | R40: 2023 | S40: =R40+1 -> 2024 | T40: =S40+1 -> 2025 | U40: =T40+1 -> 2026 | V40: =U40+1 -> 2027 | W40: =V40+1 -> 2028 | X40: =W40+1 -> 2029 | Y40: =X40+1 -> 2030 | Z40: =Y40+1 -> 2031 | ... AB40: =AA40+1 -> 2033
B41: 0.43 | C41: Paybacks | E41: Source | Q41: 16-25 | R41: =VLOOKUP($Q41,$B$17:$N$22,R$39,FALSE)*$B$40*$B$41*$B$42 -> $ 346,752,000 | S41: =VLOOKUP($Q41,$B$17:$N$22,S$39,FALSE)*$B$40*$B$41*$B$42 -> $ 345,018,240 | T41: =VLOOKUP($Q41,$B$17:$N$22,T$39,FALSE)*$B$40*$B$41*$B$42 -> $ 343,293,149 | U41: =VLOOKUP($Q41,$B$17:$N$22,U$39,FALSE)*$B$40*$B$41*$B$42 -> $ 346,726,080 | V41: =VLOOKUP($Q41,$B$17:$N$22,V$39,FALSE)*$B$40*$B$41*$B$42 -> $ 350,193,341 | W41: =VLOOKUP($Q41,$B$17:$N$22,W$39,FALSE)*$B$40*$B$41*$B$42 -> $ 353,695,275 | X41: =VLOOKUP($Q41,$B$17:$N$22,X$39,FALSE)*$B$40*$B$41*$B$42 -> $ 351,926,798 | Y41: =VLOOKUP($Q41,$B$17:$N$22,Y$39,FALSE)*$B$40*$B$41*$B$42 -> $ 350,167,164 | ... AB41: =VLOOKUP($Q41,$B$17:$N$22,AB$39,FALSE)*$B$40*$B$41*$B$42 -> $ 344,940,875
B42: 15000 | C42: Average Withdrawals | E42: Source | Q42: 26-35 | R42: =VLOOKUP($Q42,$B$17:$N$22,R$39,FALSE)*$B$39*$B$41*$B$42 -> $ 3,792,600,000 | S42: =VLOOKUP($Q42,$B$17:$N$22,S$39,FALSE)*$B$39*$B$41*$B$42 -> $ 3,773,637,000 | T42: =VLOOKUP($Q42,$B$17:$N$22,T$39,FALSE)*$B$39*$B$41*$B$42 -> $ 3,754,768,815 | U42: =VLOOKUP($Q42,$B$17:$N$22,U$39,FALSE)*$B$39*$B$41*$B$42 -> $ 3,792,316,503 | V42: =VLOOKUP($Q42,$B$17:$N$22,V$39,FALSE)*$B$39*$B$41*$B$42 -> $ 3,830,239,668 | W42: =VLOOKUP($Q42,$B$17:$N$22,W$39,FALSE)*$B$39*$B$41*$B$42 -> $ 3,868,542,065 | X42: =VLOOKUP($Q42,$B$17:$N$22,X$39,FALSE)*$B$39*$B$41*$B$42 -> $ 3,849,199,355 | Y42: =VLOOKUP($Q42,$B$17:$N$22,Y$39,FALSE)*$B$39*$B$41*$B$42 -> $ 3,829,953,358 | ... AB42: =VLOOKUP($Q42,$B$17:$N$22,AB$39,FALSE)*$B$39*$B$41*$B$42 -> $ 3,772,790,825
Q43: 36-45 | R43: =VLOOKUP($Q43,$B$17:$N$23,R$39,FALSE)*$B$38*$B$41*$B$42 -> $ 20,588,400,000 | S43: =VLOOKUP($Q43,$B$17:$N$23,S$39,FALSE)*$B$38*$B$41*$B$42 -> $ 20,485,458,000 | T43: =VLOOKUP($Q43,$B$17:$N$23,T$39,FALSE)*$B$38*$B$41*$B$42 -> $ 20,383,030,710 | U43: =VLOOKUP($Q43,$B$17:$N$23,U$39,FALSE)*$B$38*$B$41*$B$42 -> $ 20,586,861,017 | V43: =VLOOKUP($Q43,$B$17:$N$23,V$39,FALSE)*$B$38*$B$41*$B$42 -> $ 20,792,729,627 | W43: =VLOOKUP($Q43,$B$17:$N$23,W$39,FALSE)*$B$38*$B$41*$B$42 -> $ 21,000,656,924 | X43: =VLOOKUP($Q43,$B$17:$N$23,X$39,FALSE)*$B$38*$B$41*$B$42 -> $ 20,895,653,639 | Y43: =VLOOKUP($Q43,$B$17:$N$23,Y$39,FALSE)*$B$38*$B$41*$B$42 -> $ 20,791,175,371 | ... AB43: =VLOOKUP($Q43,$B$17:$N$23,AB$39,FALSE)*$B$38*$B$41*$B$42 -> $ 20,480,864,479
Q44: 46-55 | R44: =VLOOKUP($Q44,$B$17:$N$23,R$39,FALSE)*$B$37*$B$41*$B$42 -> $ 43,344,000,000 | S44: =VLOOKUP($Q44,$B$17:$N$23,S$39,FALSE)*$B$37*$B$41*$B$42 -> $ 43,127,280,000 | T44: =VLOOKUP($Q44,$B$17:$N$23,T$39,FALSE)*$B$37*$B$41*$B$42 -> $ 42,911,643,600 | U44: =VLOOKUP($Q44,$B$17:$N$23,U$39,FALSE)*$B$37*$B$41*$B$42 -> $ 43,340,760,036 | V44: =VLOOKUP($Q44,$B$17:$N$23,V$39,FALSE)*$B$37*$B$41*$B$42 -> $ 43,774,167,636 | W44: =VLOOKUP($Q44,$B$17:$N$23,W$39,FALSE)*$B$37*$B$41*$B$42 -> $ 44,211,909,313 | X44: =VLOOKUP($Q44,$B$17:$N$23,X$39,FALSE)*$B$37*$B$41*$B$42 -> $ 43,990,849,766 | Y44: =VLOOKUP($Q44,$B$17:$N$23,Y$39,FALSE)*$B$37*$B$41*$B$42 -> $ 43,770,895,517 | ... AB44: =VLOOKUP($Q44,$B$17:$N$23,AB$39,FALSE)*$B$37*$B$41*$B$42 -> $ 43,117,609,430
...

Sheet Module 2
B3: Robo-Advisor Annual Income Statement, $M
C4: 2023 | D4: =C4+1 -> 2024 | E4: =D4+1 -> 2025 | F4: =E4+1 -> 2026 | G4: =F4+1 -> 2027 | H4: =G4+1 -> 2028 | I4: =H4+1 -> 2029 | J4: =I4+1 -> 2030 | K4: =J4+1 -> 2031 | ... M4: =L4+1 -> 2033 | O4: Assumptions
B5: Revenue | D5: =D6*HLOOKUP(D4,'Module 1'!$D$5:$N$11,6,FALSE) -> $39.89 | E5: =E6*HLOOKUP(E4,'Module 1'!$D$5:$N$11,6,FALSE) -> $59.35 | F5: =F6*HLOOKUP(F4,'Module 1'!$D$5:$N$11,6,FALSE) -> $83.96 | G5: =G6*HLOOKUP(G4,'Module 1'!$D$5:$N$11,6,FALSE) -> $114.10 | H5: =H6*HLOOKUP(H4,'Module 1'!$D$5:$N$11,6,FALSE) -> $150.42 | I5: =I6*HLOOKUP(I4,'Module 1'!$D$5:$N$11,6,FALSE) -> $172.85 | J5: =J6*HLOOKUP(J4,'Module 1'!$D$5:$N$11,6,FALSE) -> $225.01 | K5: =K6*HLOOKUP(K4,'Module 1'!$D$5:$N$11,6,FALSE) -> $286.18 | ... M5: =M6*HLOOKUP(M4,'Module 1'!$D$5:$N$11,6,FALSE) -> $438.80 | O5: Initial investment | R5: -400
B6: Market Share | D6: =R7 -> 2% | E6: =D6+$R8 -> 2.5% | F6: =E6+$R8 -> 3.0% | G6: =F6+$R8 -> 3.5% | H6: =G6+$R8 -> 4.0% | I6: =H6+$R8 -> 4.5% | J6: =I6+$R8 -> 5.0% | K6: =J6+$R8 -> 5.5% | L6: =K6+$R8 -> 6.0% | M6: =L6+$R8 -> 6.5% | O6: Operating expense | R6: -70
B7: Operating cost | D7: =R6 -> ($70.00) | E7: =D7*(1+$R9) -> ($71.40) | F7: =E7*(1+$R9) -> ($72.83) | G7: =F7*(1+$R9) -> ($74.28) | H7: =G7*(1+$R9) -> ($75.77) | I7: =H7*(1+$R9) -> ($77.29) | J7: =I7*(1+$R9) -> ($78.83) | K7: =J7*(1+$R9) -> ($80.41) | L7: =K7*(1+$R9) -> ($82.02) | M7: =L7*(1+$R9) -> ($83.66) | O7: Initial market capture | R7: 0.02
B8: Initial capital | C8: =R5 -> ($400) | O8: Incremental market capture | R8: 0.005
B9: Net Income | C9: =C5+C7+C8 -> ($400) | D9: =D5+D7+D8 -> ($30) | E9: =E5+E7+E8 -> ($12) | F9: =F5+F7+F8 -> $11 | G9: =G5+G7+G8 -> $40 | H9: =H5+H7+H8 -> $75 | I9: =I5+I7+I8 -> $96 | J9: =J5+J7+J8 -> $146 | ... M9: =M5+M7+M8 -> $355 | O9: Inflation | R9: 0.02
O10: Discount Rate | R10: 0.03 | S10: Source
B11: Cumulative Revenue | D11: =D5 -> $39.89 | E11: =E5+D11 -> $99.24 | F11: =F5+E11 -> $183.20 | G11: =G5+F11 -> $297.29 | H11: =H5+G11 -> $447.72 | I11: =I5+H11 -> $620.56 | J11: =J5+I11 -> $845.57 | K11: =K5+J11 -> $1,131.75 | L11: =L5+K11 -> $1,488.91 | M11: =M5+L11 -> $1,927.71
B12: Cumulative Costs | C12: =C9 -> ($400) | D12: =C12+D7 -> ($470) | E12: =D12+E7 -> ($541) | F12: =E12+F7 -> ($614) | G12: =F12+G7 -> ($689) | H12: =G12+H7 -> ($764) | I12: =H12+I7 -> ($842) | J12: =I12+J7 -> ($920) | K12: =J12+K7 -> ($1,001) | ... M12: =L12+M7 -> ($1,166)
B13: Cumulative Net Income | C13: =SUM(C11:C12) -> ($400) | D13: =SUM(D11:D12) -> ($430) | E13: =SUM(E11:E12) -> ($442) | F13: =SUM(F11:F12) -> ($431) | G13: =SUM(G11:G12) -> ($391) | H13: =SUM(H11:H12) -> ($317) | I13: =SUM(I11:I12) -> ($221) | J13: =SUM(J11:J12) -> ($75) | ... M13: =SUM(M11:M12) -> $761
B16: Payback Year | C16: =C4+COUNTIF(C13:M13,"<=0") -> 2031
B17: Period (Years) | C17: =COUNTIF(C13:M13,"<=0") -> 8
B18: NPV ($M) | C18: {=NPV(R10,C9:M9)} -> $491.09
B19: IRR | C19: =IRR(C9:M9) -> 13.6%
B20: NPV, invested at start ($M) | C20: {=C9+NPV(R10,D9:M9)} -> $505.82
B21: NPV Table
B22: Discount Rate | C22: 0.005 | D22: =C22+0.5% -> 1.00% | E22: =D22+0.5% -> 1.50% | F22: =E22+0.5% -> 2.00% | G22: =F22+0.5% -> 2.50% | H22: =G22+0.5% -> 3.00% | I22: =H22+0.5% -> 3.50% | J22: =I22+0.5% -> 4.00% | K22: =J22+0.5% -> 4.50% | ... X22: =W22+0.5% -> 11.00%
B23: NPV | C23: =NPV(C$22,$C$9:$M$9) -> $709.92 | D23: =NPV(D$22,$C$9:$M$9) -> $661.33 | E23: =NPV(E$22,$C$9:$M$9) -> $615.28 | F23: =NPV(F$22,$C$9:$M$9) -> $571.65 | G23: =NPV(G$22,$C$9:$M$9) -> $530.30 | H23: =NPV(H$22,$C$9:$M$9) -> $491.09 | I23: =NPV(I$22,$C$9:$M$9) -> $453.91 | J23: =NPV(J$22,$C$9:$M$9) -> $418.64 | ... X23: =NPV(X$22,$C$9:$M$9) -> $76.74

Sheet Assumptions
C3: Market Size
D4: 2023 | E4: Growth 2024 - 2025 | F4: Growth 2026 - 2028 | G4: Growth 2029 -2033
C5: US Labor Force | D5: 168000000 | E5: -0.005 | F5: 0.01 | G5: -0.005
C6: % of Labor Force contributing to retirement accounts | D6: 50% - fixed across period
C8: Labor Force Share, by Age Group
C9: Age Bracket | D9: 2023-2033
C10: 16-25 | D10: 0.08
C11: 26-35 | D11: 0.14
C12: 36-45 | D12: 0.19
C13: 46-55 | D13: 0.2
C14: 56-70 | D14: 0.2
C15: 70+ | D15: 0.19
C17: Average Annual Income, by Age Group
C18: Age Bracket | D18: 2023 | E18: Growth 2024 - 2028 | F18: Growth 2029 - 2033
C19: 16-25 | D19: 42000 | E19: 0.025 | F19: 0.015
C20: 26-35 | D20: 51000 | E20: 0.025 | F20: 0.015
C21: 36-45 | D21: 75000 | E21: 0.025 | F21: 0.015
C22: 46-55 | D22: 80000 | E22: 0.025 | F22: 0.015
C23: 56-70 | D23: 83000 | E23: 0.025 | F23: 0.015
C24: 70+ | D24: 48000 | E24: 0.025 | F24: 0.015
C26: Percentage Gross Annual Income Contributed for Retirement, by Age Group
C27: Age Bracket | D27: 2023 | E27: 2024 - 2025 | F27: 2026 -2028 | G27: 2029 -2033
C28: 16-25 | D28: 0.06 | E28: 0.07 | F28: 0.07 | G28: 0.07
C29: 26-35 | D29: 0.08 | E29: 0.1 | F29: 0.1 | G29: 0.1
C30: 36-45 | D30: 0.12 | E30: 0.14 | F30: 0.14 | G30: 0.14
C31: 46-55 | D31: 0.16 | E31: 0.18 | F31: 0.19 | G31: 0.21
C32: 56-70 | D32: 0.18 | E32: 0.21 | F32: 0.22 | G32: 0.24
C33: 70+ | D33: 0 | E33: 0 | F33: 0 | G33: 0
C35: Robo-Advisory Management Fee Revenues
D36: 2023 | E36: 2024 - 2028 | F36: 2029 -2033
C37: Average Annualized Mgmt Fee | D37: 0.004 | E37: 0.0035 | F37: 0.003
C39: Market Share and Expenses
C40: Year | D40: Market Share (Revenue) | E40: Expenses
C41: 2023 | D41: 0 | E41: -400000000
C42: =C41+1 -> 2024 | D42: 0.02 | E42: -70000000
C43: 2025 - 2033 | D43: +0.5% per year | E43: ~2% - 3% annual expense growth rate
C45: Other Key Assumptions/Information
C46: 1. There is no prescribed discount rate or cost of capital - please use your judgement on the discount rate you apply towards evaluating this opportunity, and be prepared to justify your selection.
C47: 2. At year-end 2022 there was an estimated total accumulated Robo-Advisor AUM of $400 billion. Assume that all Robo-Advisor retirement contributions made in 2023 – 2033 are incremental annual net-contributions made to Robo-Advisors on a year-over-year basis.
C48: 3. Since assets under management is driven by the combination of contributions, market appreciation, and outflows (withdrawals), you should account for all these factors when forecasting Robo Advisor AUM. Be prepared to justify your assumptions.
...

Sheet Chart
C3: ='Module 1'!C5 -> 2022 | D3: ='Module 1'!D5 -> 2023 | E3: ='Module 1'!E5 -> 2024 | F3: ='Module 1'!F5 -> 2025 | G3: ='Module 1'!G5 -> 2026 | H3: ='Module 1'!H5 -> 2027 | I3: ='Module 1'!I5 -> 2028 | J3: ='Module 1'!J5 -> 2029 | ... N3: ='Module 1'!N5 -> 2033
B4: $ AUM | C4: ='Module 1'!C9 -> $ 400,000 | D4: ='Module 1'!D9-'Module 1'!D7 -> $ 420,000 | E4: ='Module 1'!E9-'Module 1'!E7 -> $ 492,758 | F4: ='Module 1'!F9-'Module 1'!F7 -> $ 598,380 | G4: ='Module 1'!G9-'Module 1'!G7 -> $ 712,192 | H4: ='Module 1'!H9-'Module 1'!H7 -> $ 839,562 | I4: ='Module 1'!I9-'Module 1'!I7 -> $ 977,968 | J4: ='Module 1'!J9-'Module 1'!J7 -> $ 1,128,180 | K4: ='Module 1'!K9-'Module 1'!K7 -> $ 1,344,351 | ... N4: ='Module 1'!N9-'Module 1'!N7 -> $ 2,083,422
B5: Robo-Advisor Market Size | D5: ='Module 1'!D7 -> $ 49,294 | E5: ='Module 1'!E7 -> $ 77,127 | F5: ='Module 1'!F7 -> $ 79,898 | G5: ='Module 1'!G7 -> $ 87,390 | H5: ='Module 1'!H7 -> $ 91,836 | I5: ='Module 1'!I7 -> $ 96,489 | J5: ='Module 1'!J7 -> $ 152,155 | K5: ='Module 1'!K7 -> $ 155,721 | ... N5: ='Module 1'!N7 -> $ 166,835
D6: ='Module 1'!D10 -> $1,877 | E6: ='Module 1'!E10 -> $1,995 | F6: ='Module 1'!F10 -> $2,374 | G6: ='Module 1'!G10 -> $2,799 | H6: ='Module 1'!H10 -> $3,260 | I6: ='Module 1'!I10 -> $3,761 | J6: ='Module 1'!J10 -> $3,841 | K6: ='Module 1'!K10 -> $4,500 | ... N6: ='Module 1'!N10 -> $6,751
C8: =SUM(C4:C5) -> $400,000 | D8: =SUM(D4:D5) -> $469,294 | E8: =SUM(E4:E5) -> $569,886 | F8: =SUM(F4:F5) -> $678,278 | G8: =SUM(G4:G5) -> $799,582 | H8: =SUM(H4:H5) -> $931,398 | I8: =SUM(I4:I5) -> $1,074,457 | J8: =SUM(J4:J5) -> $1,280,335 | ... N8: =SUM(N4:N5) -> $2,250,257

Sheet Dropdowns
C2: Inflation | E2: 16-25 Bracket | G2: Discount Rate | I2: Investment | K2: Contribution Growth | M2: Market Appreciation
C3: 0.02 | E3: 1 | G3: 0 | I3: -400 | K3: 0 | M3: 0
C4: =C3+0.1% -> 2.1% | E4: =E3-5% -> 95% | G4: =G3+0.5% -> 0.5% | I4: =I3+25 -> ($375) | K4: 0.005 | M4: 0.01
C5: =C4+0.1% -> 2.2% | E5: =E4-5% -> 90% | G5: =G4+0.5% -> 1.0% | I5: =I4+25 -> ($350) | K5: 0.01 | M5: 0.02
C6: =C5+0.1% -> 2.3% | E6: =E5-5% -> 85% | G6: =G5+0.5% -> 1.5% | I6: =I5+25 -> ($325) | K6: 0.015 | M6: 0.03
C7: =C6+0.1% -> 2.4% | E7: =E6-5% -> 80% | G7: =G6+0.5% -> 2.0% | I7: =I6+25 -> ($300) | K7: 0.02 | M7: 0.04
C8: =C7+0.1% -> 2.5% | E8: =E7-5% -> 75% | G8: =G7+0.5% -> 2.5% | I8: =I7+25 -> ($275) | K8: 0.025 | M8: 0.05
C9: =C8+0.1% -> 2.6% | E9: =E8-5% -> 70% | G9: =G8+0.5% -> 3.0% | I9: =I8+25 -> ($250) | K9: 0.03 | M9: 0.06
C10: =C9+0.1% -> 2.7% | E10: =E9-5% -> 65% | G10: =G9+0.5% -> 3.5% | I10: =I9+25 -> ($225) | M10: 0.07
C11: =C10+0.1% -> 2.8% | E11: =E10-5% -> 60% | G11: =G10+0.5% -> 4.0% | I11: =I10+25 -> ($200) | M11: 0.08
C12: =C11+0.1% -> 2.9% | E12: =E11-5% -> 55% | G12: =G11+0.5% -> 4.5% | I12: =I11+25 -> ($175) | M12: 0.09
C13: =C12+0.1% -> 3.0% | E13: =E12-5% -> 50% | G13: =G12+0.5% -> 5.0% | I13: =I12+25 -> ($150) | M13: 0.1
E14: =E13-5% -> 45% | G14: =G13+0.5% -> 5.5% | I14: =I13+25 -> ($125)
E15: =E14-5% -> 40% | G15: =G14+0.5% -> 6.0% | I15: =I14+25 -> ($100)
E16: =E15-5% -> 35% | G16: =G15+0.5% -> 6.5% | I16: =I15+25 -> ($75)
E17: =E16-5% -> 30% | G17: =G16+0.5% -> 7.0% | I17: =I16+25 -> ($50)
E18: =E17-5% -> 25% | G18: =G17+0.5% -> 7.5% | I18: =I17+25 -> ($25)
E19: =E18-5% -> 20% | G19: =G18+0.5% -> 8.0% | I19: =I18+25 -> $0
E20: =E19-5% -> 15% | G20: =G19+0.5% -> 8.5%
E21: =E20-5% -> 10% | G21: =G20+0.5% -> 9.0%
E22: =E21-5% -> 5% | G22: =G21+0.5% -> 9.5%
E23: =E22-5% -> 0% | G23: =G22+0.5% -> 10.0%
G24: =G23+0.5% -> 10.5%
G25: =G24+0.5% -> 11.0%
